D:\Sotfware\Anaconda\install\envs\pytorch_38\lib\site-packages\huggingface_hub\file_download.py:795: FutureWarning: `resume_download` is deprecated and will be removed in version 1.0.0. Downloads always resume when possible. If you want to force a new download, use `force_download=True`.
  warnings.warn(
Removing incomplete file 'model\qwen2.5-7b-instruct\.cache\huggingface\download\model-00001-of-00004.safetensors.a1333e6293854747c481288ea83b348226af178dd565c49b6f9495ba1966aba7.incomplete' (hf_transfer=True)
Downloading 'model-00001-of-00004.safetensors' to 'model\qwen2.5-7b-instruct\.cache\huggingface\download\model-00001-of-00004.safetensors.a1333e6293854747c481288ea83b348226af178dd565c49b6f9495ba1966aba7.incomplete'
Traceback (most recent call last):
  File "D:\Sotfware\Anaconda\install\envs\pytorch_38\lib\site-packages\huggingface_hub\file_download.py", line 426, in http_get
    hf_transfer.download(
Exception: Error while removing corrupted file: 另一个程序正在使用此文件，进程无法访问。 (os error 32)

The above exception was the direct cause of the following exception:

Traceback (most recent call last):
  File "D:\Sotfware\Anaconda\install\envs\pytorch_38\lib\runpy.py", line 194, in _run_module_as_main
    return _run_code(code, main_globals, None,
  File "D:\Sotfware\Anaconda\install\envs\pytorch_38\lib\runpy.py", line 87, in _run_code
    exec(code, run_globals)
  File "D:\Sotfware\Anaconda\install\envs\pytorch_38\Scripts\huggingface-cli.exe\__main__.py", line 7, in <module>
  File "D:\Sotfware\Anaconda\install\envs\pytorch_38\lib\site-packages\huggingface_hub\commands\huggingface_cli.py", line 57, in main
    service.run()
  File "D:\Sotfware\Anaconda\install\envs\pytorch_38\lib\site-packages\huggingface_hub\commands\download.py", line 153, in run
    print(self._download())  # Print path to downloaded files
  File "D:\Sotfware\Anaconda\install\envs\pytorch_38\lib\site-packages\huggingface_hub\commands\download.py", line 187, in _download
    return snapshot_download(
  File "D:\Sotfware\Anaconda\install\envs\pytorch_38\lib\site-packages\huggingface_hub\utils\_validators.py", line 114, in _inner_fn
    return fn(*args, **kwargs)
  File "D:\Sotfware\Anaconda\install\envs\pytorch_38\lib\site-packages\huggingface_hub\_snapshot_download.py", line 294, in snapshot_download
    _inner_hf_hub_download(file)
  File "D:\Sotfware\Anaconda\install\envs\pytorch_38\lib\site-packages\huggingface_hub\_snapshot_download.py", line 270, in _inner_hf_hub_download
    return hf_hub_download(
  File "D:\Sotfware\Anaconda\install\envs\pytorch_38\lib\site-packages\huggingface_hub\utils\_validators.py", line 114, in _inner_fn
    return fn(*args, **kwargs)
  File "D:\Sotfware\Anaconda\install\envs\pytorch_38\lib\site-packages\huggingface_hub\file_download.py", line 840, in hf_hub_download
    return _hf_hub_download_to_local_dir(
  File "D:\Sotfware\Anaconda\install\envs\pytorch_38\lib\site-packages\huggingface_hub\file_download.py", line 1136, in _hf_hub_download_to_local_dir
    _download_to_tmp_and_move(
  File "D:\Sotfware\Anaconda\install\envs\pytorch_38\lib\site-packages\huggingface_hub\file_download.py", line 1543, in _download_to_tmp_and_move
    http_get(
  File "D:\Sotfware\Anaconda\install\envs\pytorch_38\lib\site-packages\huggingface_hub\file_download.py", line 437, in http_get
    raise RuntimeError(
RuntimeError: An error occurred while downloading using `hf_transfer`. Consider disabling HF_HUB_ENABLE_HF_TRANSFER for better error handling.
